Workbook
Name AAA: '[2]28-02-97'!#REF!
Name AAA: '[2]28-02-97'!#REF!
Name ACCRUAL: '[3]Acc&Prep'!$A$1:$J$700
Name ACCRUALS: '[3]Acc&Prep'!$D$701
Name Beg_Bal: #REF!
Name Beg_Bal: #REF!
Name CCY: #REF!
Name CCY: #REF!
Name copy.P_LtoAC: #REF!
Name copy.P_LtoAC: #REF!
Name copyCons_toAA: #REF!
Name copyCons_toAA: #REF!
Name Cum_Int: #REF!
Name Cum_Int: #REF!
Name Data: #REF!
Name Data: #REF!
Name data84: '[4]Purchase Order'!$E$52
Name Def.Income: #REF!
Name Def.Income: #REF!
Name Direct: [3]TB!$42:$124
Name dtrj: DATE(YEAR([5]Payments!Loan_Start),MONTH([5]Payments!Loan_Start)+Payment_Number,DAY([5]Payments!Loan_Start))
Name dtrj: DATE(YEAR([5]Payments!Loan_Start),MONTH([5]Payments!Loan_Start)+Payment_Number,DAY([5]Payments!Loan_Start))
Name dtrj: DATE(YEAR([5]Payments!Loan_Start),MONTH([5]Payments!Loan_Start)+Payment_Number,DAY([5]Payments!Loan_Start))
Name dtrj: DATE(YEAR([5]Payments!Loan_Start),MONTH([5]Payments!Loan_Start)+Payment_Number,DAY([5]Payments!Loan_Start))
Name dtrj: DATE(YEAR([5]Payments!Loan_Start),MONTH([5]Payments!Loan_Start)+Payment_Number,DAY([5]Payments!Loan_Start))
Name dtrj: DATE(YEAR([5]Payments!Loan_Start),MONTH([5]Payments!Loan_Start)+Payment_Number,DAY([5]Payments!Loan_Start))
Name dtrj: DATE(YEAR([5]Payments!Loan_Start),MONTH([5]Payments!Loan_Start)+Payment_Number,DAY([5]Payments!Loan_Start))
Name dtrj: DATE(YEAR([5]Payments!Loan_Start),MONTH([5]Payments!Loan_Start)+Payment_Number,DAY([5]Payments!Loan_Start))
Name End_Bal: #REF!
Name End_Bal: #REF!
Name Extra_Pay: #REF!
Name Extra_Pay: #REF!
Name Full_Print: #REF!
Name Full_Print: #REF!
Name Header_Row: ROW(#REF!)
Name Int: #REF!
Name Int: #REF!
Name Interest_Rate: #REF!
Name Interest_Rate: #REF!
Name Last_Row: IF('اجمالى راس المال'!Values_Entered,[6]!Header_Row+'اجمالى راس المال'!Number_of_Payments,[6]!Header_Row)
Name Last_Row: IF('الايرادات '!Values_Entered,Header_Row+'الايرادات '!Number_of_Payments,Header_Row)
Name Last_Row: IF(Values_Entered,Header_Row+Number_of_Payments,Header_Row)
Name Loan_Amount: #REF!
Name Loan_Amount: #REF!
Name Loan_Start: #REF!
Name Loan_Start: #REF!
Name Loan_Years: #REF!
Name Loan_Years: #REF!
Name MonthEnding: #REF!
Name MonthEnding: #REF!
Name nnn: Scheduled_Payment+Extra_Payment
Name nnn: Scheduled_Payment+Extra_Payment
Name nnn: Scheduled_Payment+Extra_Payment
Name nnn: Scheduled_Payment+Extra_Payment
Name nnn: Scheduled_Payment+Extra_Payment
Name nnn: Scheduled_Payment+Extra_Payment
Name nnn: Scheduled_Payment+Extra_Payment
Name nnn: Scheduled_Payment+Extra_Payment
Name Num_Pmt_Per_Year: #REF!
Name Num_Pmt_Per_Year: #REF!

Sheet قاعدة بيانات  
A2: رقم التسجيل | B2: المورد | C2: العنوان | D2: النوع | F2: القسم | G2: التصنيف | I2: نوع المصروف | K2: الكود | L2: اسم الموظف | M2: رقم البطاقه | N2: الوظيفه | O2: الاداره | P2: القسم | Q2: الفرع | R2: تاريخ التعين | S2: تاريخ الاستقاله | T2: الراتب
A3: 535694423 | B3: مانى فيللوز لتكنولوجيا المعلومات وادارة المشروعات | C3: ق44الحي الاول التجمع الخامس القاهره الجديده | D3: مبيعات | E3: =A3 -> 535694423 | F3: الادراه العليا | G3: قيمه | I3: رصيد اول | K3: 88888888 | L3: زينب عبد الكريم عبد العليم الحفناوى | M3: 2908180100628 | N3: وكيل تحصيل هاتفى | O3: مانى فيللوز | P3: التحصيل | Q3: القاهرة | R3: 45545
A4: 643247289 | B4: سيمبل للحلول والتكنولوجيا المالية | C4: الشيخ زايد | D4: مبيعات | E4: =A4 -> 643247289 | F4: الادراه الماليه | G4: القاهرة | I4: اصول | K4: 8 | L4: امل صبرى | M4: 2908180100628 | N4: وكيل تحصيل هاتفى | O4: ميد تقسيط - ماني فيللوز | P4: التحصيل | Q4: المنصورة
A5: 200196375 | B5: شركه رايه للالكترونيات | C5: قسم أول 6 أكتوبر, الجيزه, EG | D5: مبيعات | E5: =A5 -> 200196375 | F5: اداره الموارد البشريه | G5: المنصورة | I5: ض 14% | K5: 1 | L5: احمد شريف سليمان امين سليمان | M5: 29903040101135 | N5: نائب كبير مشرفى تحصيل | O5: متعدد | P5: التحصيل | Q5: القاهرة | R5: 44896
A6: 200029665 | B6: بنك الإسكندرية | C6: شارع قصر النيل | D6: مبيعات | E6: =A6 -> 200029665 | F6: اداره الخدمات المعاونه | G6: القانونيه | I6: انتقالات | K6: 2 | L6: علاء محمد عوض جاد الله | M6: 28602012105474 | N6: مدير تحصيل | O6: التحصيل | P6: التحصيل | Q6: المنصورة
A7: 204896843 | B7: بنك كريدي اجريكول مصر | C7: قسم التجمع الخامس (أول القاهرة الجديدة ), القاهرة, EG | D7: مبيعات | E7: =A7 -> 204896843 | F7: الاداره القانونيه | G7: الخدمات القانونية | I7: صيانه | K7: 4 | L7: وليد عبد الكريم عبد العليم | M7: 28808250100593 | N7: مدير تحصيل | O7: التحصيل | P7: التحصيل | Q7: القاهرة
A8: 547823509 | B8: فاليو لخدمات البيع والتقسيط | C8: القرية الذكية ك 29 طريق ابورواش | D8: مبيعات | E8: =A8 -> 547823509 | F8: اداري | G8: 25 ج | I8: ايجارات | K8: 5 | L8: باسم صلاح عبد الله قوشتى | M8: 28303120101712 | N8: المستشار القانوني | O8: الشئون القانونية | P8: الادارى | Q8: القاهرة
A9: 204901448 | B9: بنك البركة مصر | E9: =A9 -> 204901448 | F9: شركه رايه - تحصيل | G9: 20 أ | I9: جاري شركاء | K9: 9 | L9: عمرو عصام بدر الدين زكي | M9: 29808080106196 | N9: نائب مدير الإدارة القانونية | O9: الشئون القانونية | P9: الادارى | Q9: القاهرة | R9: 44927
A10: 547768524 | B10: امان لتمويل المشروعات | D10: مبيعات | E10: =A10 -> 547768524 | F10: شركه رايه - قانونيه | G10: الدور 15 | I10: رسوم | K10: 10 | L10: عبد المنعم مجدى عبدربه محمد هلهل | M10: 28609291403433 | N10: المدير العام | O10: التحصيل | P10: التحصيل | Q10: القاهرة
A11: 669384283 | B11: ميد للتقسيط | C11: 21 شارع جامعة الدول المهندسين | D11: مبيعات | E11: =A11 -> 669384283 | F11: شركه فاليو - تحصيل | G11: الصعيد | I11: أدوات نظافة | K11: 19 | L11: سحر اوسامة احمد محمد | M11: 29611110104501 | N11: مشرف تحصيل | O11: شركة فاليو | P11: التحصيل | Q11: القاهرة | R11: 45209
A12: 200196375 | B12: شركه رايه قانونى | C12: قسم أول 6 أكتوبر, الجيزه, EG | D12: مبيعات | E12: =A12 -> 200196375 | F12: شركه فاليو - قانونيه | G12: المقر الجديد | I12: سباكه | K12: 20 | L12: عبد العزيز صلاح عبد العزيز على حسن | M12: 29703150100399 | N12: مشرف قضائى | O12: الشئون القانونية | P12: الادارى | Q12: القاهرة | R12: 45003
A13: 200196375 | B13: شركه رايه كوربت | F13: شركه بلنك - تحصيل | I13: انترنت | K13: 25 | L13: منى احمد طه احمد سعد | M13: 27312250101345 | N13: خدمات معاونة | O13: الخدمات المعاونة | P13: الادارى | Q13: القاهرة | R13: 44959
A14: 757680283 | B14: فورى لتكنولوجيا المعلومات التجارية | C14: قطعه اف 12 على بى 221 القريه الذكيه الحى المالى الجيزه قسم الجيزة, الجيزه, EG | F14: شركه بلنك - قانونيه | I14: بوفيه | K14: 31 | L14: محمود النادى أبو الحسن احمد | M14: 28504108800236 | N14: كبير مشرفى تحصيل | O14: بنك كريدى اجريكول | P14: التحصيل | Q14: القاهرة | R14: 45020
A15: 547823509 | B15: فاليو قانونى | F15: شركه سمبيل - تحصيل | I15: اكراميات | K15: 35 | L15: رحمة مصطفى خلف الله حسانين | M15: 30111210101161 | N15: منسق بيانات | O15: منسقى البيانات | P15: الادارى | Q15: القاهرة | R15: 45285
A16: 623670232 | B16: بلنك قانونى | C16: قسم أول 6 أكتوبر, الجيزه, EG | D16: مبيعات | F16: بنك الاسكندريه - تحصيل | I16: تليفونات | K16: 45 | L16: محمد مجدى ربيع عبد الغنى جاد | M16: 28409261402239 | N16: مشرف تحصيل | O16: شركة فاليو | P16: التحصيل | Q16: القاهرة | R16: 45042
A17: 669384283 | B17: ميد قانونى | F17: بنك كريدي - تحصيل | I17: سلف | K17: 54 | L17: رحاب عبد الهادى احمد بدوى | M17: 28706021401264 | N17: مشرف تحصيل | O17: بنك الإسكندرية / شركة سهولة | P17: التحصيل | Q17: القاهرة | R17: 45053
A18: 720831954 | B18: بى ام للتمويل الاستهلاكى | C18: 118وان قطامية أبراج المرشدى | D18: مبيعات | F18: شركه ماني - تحصيل | I18: ادوات مكتبيه | K18: 60 | L18: مروة مصطفى على جاد | M18: 29912120104665 | N18: مشرف تحصيل | O18: شركة راية | P18: التحصيل | Q18: القاهرة | R18: 45062
A19: 332885968 | B19: شركه مشروعى للتجاره | F19: فيزا المحكمة | K19: 277 | L19: ماجد الالفي | N19: محامي | O19: الشئون القانونية | P19: القانونية
A20: 628786476 | B20: شركه حالا للتمويل الاستهلاكى
A21: 499041712 | B21: شركه تساهيل للتمويل
B22: اور للتمويل الاستهلاكى -وسيلة قانونى | F22: شركه ميد تقسيط - تحصيل | I22: ضيافه | K22: 62 | L22: محمد مجدى السيد عبد الدايم | M22: 29710280100451 | N22: مشرف قضائى | O22: الشئون القانونية | P22: الادارى | Q22: القاهرة | R22: 45066
A23: 578890496 | B23: بلتون للتمويل الاستهلاكى سفن | C23: مجمع جاليريا40وحده304محور كريزي ووتر الشيخ زايد | F23: تشغيل القاهره | I23: كهرباء | K23: 64 | L23: تريز سامى رزق شحاته | M23: 28712200101702 | N23: مدير موارد بشرية | O23: الموارد البشرية | P23: الادارى | Q23: القاهرة | R23: 45081
A24: 313018103 | B24: تنميه لخدمات المشروعات متناهيه الصغر | C24: 0 / 9 شياخه المعادى الجديده قسم البساتين شارع أحمد عبد ا | F24: تشغيل المنصورة | I24: نجارة | K24: 71 | L24: ندى محمد سعد محمد | M24: 30110042101308 | N24: وكيل تحصيل هاتفى | O24: بنك كريدى اجريكول | P24: التحصيل | Q24: القاهرة | R24: 45081
A25: 204892465 | B25: ميد بنك | F25: تشغيل الشركه | I25: مرتبات -اداره التحصيل | K25: 83 | L25: حبيبه احمد سلطان منصور عويس | M25: 30312060105762 | N25: مشرف تحصيل | O25: شركة ماني فيللوز | P25: التحصيل | Q25: القاهرة | R25: 45111
A26: 724133259 | B26: اور للتمويل الاستهلاكى -وسيلة | C26: الوحده رقم A 111 -مبنى اركاديا مول كورنيش النيل بولاق | F26: عقود الإنتاج | I26: مرتبات -الشئون القانونية | K26: 97 | L26: ندى محمد محمود عبد المقصود | M26: 30106051400523 | N26: وكيل تحصيل هاتفى | O26: شركة ميد تقسيط | P26: التحصيل | Q26: القاهرة | R26: 45395
A27: 547823509 | B27: فاليو | F27: شركة بلتون | I27: عمولات | K27: 119 | L27: مصطفى جميل عبد الفتاح محمد شاهين | M27: 30302090103319 | N27: وكيل تحصيل | O27: بنك كريدى اجريكول | P27: التحصيل | Q27: القاهرة | R27: 45326
A28: 578890496 | B28: سفن | F28: إدارة التحصيل | I28: استشارات | K28: 125 | L28: زينب محمود محمد محمود صالح | M28: 30108160102829 | N28: وكيل تحصيل هاتفى | O28: شركة ماني فيللوز | P28: التحصيل | Q28: القاهرة | R28: 45326
A29: 725632186 | B29: شهرى للتمويل الاستهلاكى | F29: المصرية للتمويل العقارى | I29: رصيد | K29: 126 | L29: حبيبة عادل بدرالدين احمد | M29: 30107110104522 | N29: وكيل تحصيل هاتفى | O29: شركة ماني فيللوز | P29: التحصيل | Q29: القاهرة | R29: 45326
B30: سهولة قانونى | F30: منسقى البيانات | I30: تبرعات | K30: 127 | L30: احمد عوض عباس عوض كشك | M30: 29103071200577 | N30: نائب كبير مشرفى تحصيل | P30: التحصيل | Q30: المنصورة | R30: 45139
A31: 694058882 | B31: شركة إرادة لتمويل المشروعات | C31: 13 ج شارع احمد كامل تقسيم اللاسلكي المعادي القاهرة | F31: شركة سهولة | I31: تمويل البنك | K31: 129 | L31: نانسى يوسف عزيز يوسف | M31: 28908081201843 | N31: نائب مدير الإدارة القانونية | O31: الشئون القانونية | P31: الادارى | Q31: المنصورة | R31: 45150
B32: تنميه قانوني | F32: شركه ميد تقسيط - قانونية | I32: تامين | K32: 130 | L32: عبد الرحمن عوض عباس عوض كشك | M32: 29909131202315 | N32: مشرف تحصيل | P32: التحصيل | Q32: المنصورة | R32: 45139
A33: 671968785 | B33: الكان فاينانس للخدمات المالية الحديثة | F33: شركة هيما بلاستيك | I33: سمسره | K33: 131 | L33: امانى طارق إبراهيم عبد الحميد | M33: 29501011262064 | N33: منسق بيانات | O33: منسقى البيانات | P33: الادارى | Q33: المنصورة | R33: 45145
B34: سيجما كوم | F34: شركة وسيلة | I34: تمويل خزينه | K34: 133 | L34: نادين عماد منصور محمد | M34: 30106141202127 | N34: رئيس فريق عمل | P34: التحصيل | Q34: المنصورة | R34: 45146
F35: شركة تنمية | I35: مكافات | K35: 136 | L35: بهاء محمد السيد صالح أبو حسين | M35: 28403211200572 | N35: رئيس فريق عمل | P35: التحصيل | Q35: المنصورة | R35: 45139
F36: شركة جلوبال | I36: مرتبات -الادارة المالية | K36: 137 | L36: محمد وفيق إبراهيم عبد المعطى | M36: 28605211200574 | N36: مشرف تحصيل | P36: التحصيل | Q36: المنصورة | R36: 45139
F37: اى اف اس للتخصيم | I37: مرتبات -اداره الموارد البشرية | K37: 148 | L37: امال كمال عبد الله عبد الحليم | M37: 29805050105684 | N37: منسق بيانات | O37: منسقى البيانات | P37: الادارى | Q37: القاهرة | R37: 45164
F38: بنك البركة | I38: مرتبات -الشئون الإدارية | K38: 150 | L38: هدى حسن السيد على الضوى | M38: 30006102101386 | N38: منسق بيانات | O38: منسقى البيانات | P38: الادارى | Q38: القاهرة | R38: 45167
F39: شركة امان | I39: مرتبات -الخدمات المعاونة | K39: 151 | L39: احمد عبد الباسط عبد السلام محمد | M39: 29805101502713 | N39: محاسب | O39: المالية | P39: الادارى | Q39: القاهرة | R39: 45171
A40: 591872528 | B40: الجارحى للاستيراد والتصدير | C40: الهرم | D40: مشتريات | F40: البنك المصرى لتنمية الصادرات | I40: تامينات اجتماعية | K40: 177 | L40: أسماء إبراهيم السيد عبد الله | M40: 30001011278168 | N40: وكيل تحصيل هاتفى | P40: التحصيل | Q40: المنصورة | R40: 45187
A41: 205354793 | B41: جملة ماركت | C41: العبور | D41: مشتريات | F41: مصر للأصول العقارية | I41: كسب العمل | K41: 197 | L41: احمد مجدى بكر على | M41: 29503120100816 | N41: وكيل تحصيل | O41: شركة فاليو | P41: التحصيل | Q41: القاهرة | R41: 45234
...

Sheet تحليلات 2024
B1: Jan | O1: Feb | AB1: Mar
A2: الإيرادات -14% | B2: القاهرة | D2: المنصورة | F2: القانونيه | H2: الخدمات القانونية | J2: قيمه | L2: الإجمالي | O2: القاهرة | Q2: المنصورة | S2: القانونيه | U2: الخدمات القانونية | W2: قيمه | Y2: الإجمالي | AB2: القاهرة | AD2: المنصورة | AF2: القانونيه | AH2: الخدمات القانونية | AJ2: قيمه | AL2: الإجمالي | AO2: القاهرة | AQ2: المنصورة | AS2: القانونيه | AU2: الخدمات القانونية | AW2: قيمه | AY2: الإجمالي
A3: شركه رايه - تحصيل | B3: 76955.623 | C3: =IFERROR((B3/$B$18),0) -> 0.11711088 | D3: 11748.009 | E3: =IFERROR((D3/$D$18),0) -> 0.067186484 | G3: =IFERROR((F3/$F$18),0) -> 0 | I3: =IFERROR((H3/$H$18),0) -> 0 | K3: =IFERROR((J3/$H$18),0) -> 0 | L3: =B3+D3+H3+J3 -> 88703.632 | M3: =IFERROR((L3/$L$18),0) -> 0.10576092 | O3: 63271.22 | P3: =IFERROR((O3/$B$18),0) -> 0.096285985 | Q3: 11430.21 | R3: =IFERROR((Q3/$D$18),0) -> 0.065369003 | T3: =IFERROR((S3/$H$18),0) -> 0 | V3: =IFERROR((U3/$H$18),0) -> 0 | X3: =IFERROR((W3/$H$18),0) -> 0 | Y3: =O3+Q3+U3+W3+S3 -> 74701.43 | Z3: =IFERROR((Y3/$L$18),0) -> 0.089066161 | AC3: =IFERROR((AB3/$B$18),0) -> 0 | AE3: =IFERROR((AD3/$D$18),0) -> 0 | AG3: =IFERROR((AF3/$H$18),0) -> 0 | AI3: =IFERROR((AH3/$H$18),0) -> 0 | AK3: =IFERROR((AJ3/$H$18),0) -> 0 | AL3: =AB3+AD3+AH3+AJ3+AF3 -> 0 | AM3: =IFERROR((AL3/$L$18),0) -> 0 | AP3: =IFERROR((AO3/$B$18),0) -> 0 | AR3: =IFERROR((AQ3/$D$18),0) -> 0 | AT3: =IFERROR((AS3/$H$18),0) -> 0 | AV3: =IFERROR((AU3/$H$18),0) -> 0 | AX3: =IFERROR((AW3/$H$18),0) -> 0 | AY3: =AO3+AQ3+AU3+AW3+AS3 -> 0 | AZ3: =IFERROR((AY3/$L$18),0) -> 0
A4: شركه رايه - قانونيه | C4: =IFERROR((B4/$B$18),0) -> 0 | E4: =IFERROR((D4/$D$18),0) -> 0 | F4: 6744.0439 | G4: =IFERROR((F4/$H$18),0) -> 0 | I4: =IFERROR((H4/$H$18),0) -> 0 | K4: =IFERROR((J4/$H$18),0) -> 0 | L4: =B4+D4+H4+J4 -> 0 | M4: =IFERROR((L4/$L$18),0) -> 0 | P4: =IFERROR((O4/$B$18),0) -> 0 | R4: =IFERROR((Q4/$D$18),0) -> 0 | T4: =IFERROR((S4/$H$18),0) -> 0 | V4: =IFERROR((U4/$H$18),0) -> 0 | X4: =IFERROR((W4/$H$18),0) -> 0 | Y4: =O4+Q4+U4+W4+S4 -> 0 | Z4: =IFERROR((Y4/$L$18),0) -> 0 | AC4: =IFERROR((AB4/$B$18),0) -> 0 | AE4: =IFERROR((AD4/$D$18),0) -> 0 | AG4: =IFERROR((AF4/$H$18),0) -> 0 | AI4: =IFERROR((AH4/$H$18),0) -> 0 | AK4: =IFERROR((AJ4/$H$18),0) -> 0 | AL4: =AB4+AD4+AH4+AJ4+AF4 -> 0 | AM4: =IFERROR((AL4/$L$18),0) -> 0 | AP4: =IFERROR((AO4/$B$18),0) -> 0 | AR4: =IFERROR((AQ4/$D$18),0) -> 0 | AT4: =IFERROR((AS4/$H$18),0) -> 0 | AV4: =IFERROR((AU4/$H$18),0) -> 0 | AX4: =IFERROR((AW4/$H$18),0) -> 0 | AY4: =AO4+AQ4+AU4+AW4+AS4 -> 0 | AZ4: =IFERROR((AY4/$L$18),0) -> 0
A5: شركه فاليو - تحصيل | B5: 140893.41 | C5: =IFERROR((B5/$B$18),0) -> 0.21441125 | D5: 6666.7715 | E5: =IFERROR((D5/$D$18),0) -> 0.038127051 | G5: =IFERROR((F5/$H$18),0) -> 0 | I5: =IFERROR((H5/$H$18),0) -> 0 | K5: =IFERROR((J5/$H$18),0) -> 0 | L5: =B5+D5+H5+J5 -> 147560.18 | M5: =IFERROR((L5/$L$18),0) -> 0.17593531 | O5: 54751.84 | P5: =IFERROR((O5/$B$18),0) -> 0.083321214 | Q5: 7112.38 | R5: =IFERROR((Q5/$D$18),0) -> 0.040675472 | T5: =IFERROR((S5/$H$18),0) -> 0 | V5: =IFERROR((U5/$H$18),0) -> 0 | X5: =IFERROR((W5/$H$18),0) -> 0 | Y5: =O5+Q5+U5+W5+S5 -> 61864.22 | Z5: =IFERROR((Y5/$L$18),0) -> 0.073760417 | AC5: =IFERROR((AB5/$B$18),0) -> 0 | AE5: =IFERROR((AD5/$D$18),0) -> 0 | AG5: =IFERROR((AF5/$H$18),0) -> 0 | AI5: =IFERROR((AH5/$H$18),0) -> 0 | AK5: =IFERROR((AJ5/$H$18),0) -> 0 | AL5: =AB5+AD5+AH5+AJ5+AF5 -> 0 | AM5: =IFERROR((AL5/$L$18),0) -> 0 | AP5: =IFERROR((AO5/$B$18),0) -> 0 | AR5: =IFERROR((AQ5/$D$18),0) -> 0 | AT5: =IFERROR((AS5/$H$18),0) -> 0 | AV5: =IFERROR((AU5/$H$18),0) -> 0 | AX5: =IFERROR((AW5/$H$18),0) -> 0 | AY5: =AO5+AQ5+AU5+AW5+AS5 -> 0 | AZ5: =IFERROR((AY5/$L$18),0) -> 0
A6: شركه فاليو - قانونيه | C6: =IFERROR((B6/$B$18),0) -> 0 | E6: =IFERROR((D6/$D$18),0) -> 0 | G6: =IFERROR((F6/$H$18),0) -> 0 | I6: =IFERROR((H6/$H$18),0) -> 0 | K6: =IFERROR((J6/$H$18),0) -> 0 | L6: =B6+D6+H6+J6+F6 -> 0 | M6: =IFERROR((L6/$L$18),0) -> 0 | P6: =IFERROR((O6/$B$18),0) -> 0 | R6: =IFERROR((Q6/$D$18),0) -> 0 | T6: =IFERROR((S6/$H$18),0) -> 0 | V6: =IFERROR((U6/$H$18),0) -> 0 | X6: =IFERROR((W6/$H$18),0) -> 0 | Y6: =O6+Q6+U6+W6+S6 -> 0 | Z6: =IFERROR((Y6/$L$18),0) -> 0 | AC6: =IFERROR((AB6/$B$18),0) -> 0 | AE6: =IFERROR((AD6/$D$18),0) -> 0 | AG6: =IFERROR((AF6/$H$18),0) -> 0 | AI6: =IFERROR((AH6/$H$18),0) -> 0 | AK6: =IFERROR((AJ6/$H$18),0) -> 0 | AL6: =AB6+AD6+AH6+AJ6+AF6 -> 0 | AM6: =IFERROR((AL6/$L$18),0) -> 0 | AP6: =IFERROR((AO6/$B$18),0) -> 0 | AR6: =IFERROR((AQ6/$D$18),0) -> 0 | AT6: =IFERROR((AS6/$H$18),0) -> 0 | AV6: =IFERROR((AU6/$H$18),0) -> 0 | AX6: =IFERROR((AW6/$H$18),0) -> 0 | AY6: =AO6+AQ6+AU6+AW6+AS6 -> 0 | AZ6: =IFERROR((AY6/$L$18),0) -> 0
A7: شركه بلنك - تحصيل | C7: =IFERROR((B7/$B$18),0) -> 0 | E7: =IFERROR((D7/$D$18),0) -> 0 | G7: =IFERROR((F7/$H$18),0) -> 0 | I7: =IFERROR((H7/$H$18),0) -> 0 | K7: =IFERROR((J7/$H$18),0) -> 0 | L7: =B7+D7+H7+J7+F7 -> 0 | M7: =IFERROR((L7/$L$18),0) -> 0 | P7: =IFERROR((O7/$B$18),0) -> 0 | R7: =IFERROR((Q7/$D$18),0) -> 0 | T7: =IFERROR((S7/$H$18),0) -> 0 | V7: =IFERROR((U7/$H$18),0) -> 0 | X7: =IFERROR((W7/$H$18),0) -> 0 | Y7: =O7+Q7+U7+W7+S7 -> 0 | Z7: =IFERROR((Y7/$L$18),0) -> 0 | AC7: =IFERROR((AB7/$B$18),0) -> 0 | AE7: =IFERROR((AD7/$D$18),0) -> 0 | AG7: =IFERROR((AF7/$H$18),0) -> 0 | AI7: =IFERROR((AH7/$H$18),0) -> 0 | AK7: =IFERROR((AJ7/$H$18),0) -> 0 | AL7: =AB7+AD7+AH7+AJ7+AF7 -> 0 | AM7: =IFERROR((AL7/$L$18),0) -> 0 | AP7: =IFERROR((AO7/$B$18),0) -> 0 | AR7: =IFERROR((AQ7/$D$18),0) -> 0 | AT7: =IFERROR((AS7/$H$18),0) -> 0 | AV7: =IFERROR((AU7/$H$18),0) -> 0 | AX7: =IFERROR((AW7/$H$18),0) -> 0 | AY7: =AO7+AQ7+AU7+AW7+AS7 -> 0 | AZ7: =IFERROR((AY7/$L$18),0) -> 0
A8: شركه بلنك - قانونيه | C8: =IFERROR((B8/$B$18),0) -> 0 | E8: =IFERROR((D8/$D$18),0) -> 0 | G8: =IFERROR((F8/$H$18),0) -> 0 | I8: =IFERROR((H8/$H$18),0) -> 0 | K8: =IFERROR((J8/$H$18),0) -> 0 | L8: =B8+D8+H8+J8+F8 -> 0 | M8: =IFERROR((L8/$L$18),0) -> 0 | P8: =IFERROR((O8/$B$18),0) -> 0 | R8: =IFERROR((Q8/$D$18),0) -> 0 | T8: =IFERROR((S8/$H$18),0) -> 0 | V8: =IFERROR((U8/$H$18),0) -> 0 | X8: =IFERROR((W8/$H$18),0) -> 0 | Y8: =O8+Q8+U8+W8+S8 -> 0 | Z8: =IFERROR((Y8/$L$18),0) -> 0 | AC8: =IFERROR((AB8/$B$18),0) -> 0 | AE8: =IFERROR((AD8/$D$18),0) -> 0 | AG8: =IFERROR((AF8/$H$18),0) -> 0 | AI8: =IFERROR((AH8/$H$18),0) -> 0 | AK8: =IFERROR((AJ8/$H$18),0) -> 0 | AL8: =AB8+AD8+AH8+AJ8+AF8 -> 0 | AM8: =IFERROR((AL8/$L$18),0) -> 0 | AP8: =IFERROR((AO8/$B$18),0) -> 0 | AR8: =IFERROR((AQ8/$D$18),0) -> 0 | AT8: =IFERROR((AS8/$H$18),0) -> 0 | AV8: =IFERROR((AU8/$H$18),0) -> 0 | AX8: =IFERROR((AW8/$H$18),0) -> 0 | AY8: =AO8+AQ8+AU8+AW8+AS8 -> 0 | AZ8: =IFERROR((AY8/$L$18),0) -> 0
A9: شركه سمبيل - تحصيل | B9: 1061.02 | C9: =IFERROR((B9/$B$18),0) -> 0.0016146576 | E9: =IFERROR((D9/$D$18),0) -> 0 | G9: =IFERROR((F9/$H$18),0) -> 0 | I9: =IFERROR((H9/$H$18),0) -> 0 | K9: =IFERROR((J9/$H$18),0) -> 0 | L9: =B9+D9+H9+J9+F9 -> 1061.02 | M9: =IFERROR((L9/$L$18),0) -> 0.0012650491 | O9: 344.34211 | P9: =IFERROR((O9/$B$18),0) -> 0.00052401896 | R9: =IFERROR((Q9/$D$18),0) -> 0 | T9: =IFERROR((S9/$H$18),0) -> 0 | V9: =IFERROR((U9/$H$18),0) -> 0 | X9: =IFERROR((W9/$H$18),0) -> 0 | Y9: =O9+Q9+U9+W9+S9 -> 344.34211 | Z9: =IFERROR((Y9/$L$18),0) -> 0.00041055746 | AC9: =IFERROR((AB9/$B$18),0) -> 0 | AE9: =IFERROR((AD9/$D$18),0) -> 0 | AG9: =IFERROR((AF9/$H$18),0) -> 0 | AI9: =IFERROR((AH9/$H$18),0) -> 0 | AK9: =IFERROR((AJ9/$H$18),0) -> 0 | AL9: =AB9+AD9+AH9+AJ9+AF9 -> 0 | AM9: =IFERROR((AL9/$L$18),0) -> 0 | AP9: =IFERROR((AO9/$B$18),0) -> 0 | AR9: =IFERROR((AQ9/$D$18),0) -> 0 | AT9: =IFERROR((AS9/$H$18),0) -> 0 | AV9: =IFERROR((AU9/$H$18),0) -> 0 | AX9: =IFERROR((AW9/$H$18),0) -> 0 | AY9: =AO9+AQ9+AU9+AW9+AS9 -> 0 | AZ9: =IFERROR((AY9/$L$18),0) -> 0
A10: بنك الاسكندريه - تحصيل | B10: 283688.43 | C10: =IFERROR((B10/$B$18),0) -> 0.43171635 | D10: 123009.94 | E10: =IFERROR((D10/$D$18),0) -> 0.7034899 | G10: =IFERROR((F10/$H$18),0) -> 0 | I10: =IFERROR((H10/$H$18),0) -> 0 | K10: =IFERROR((J10/$H$18),0) -> 0 | L10: =B10+D10+H10+J10+F10 -> 406698.38 | M10: =IFERROR((L10/$L$18),0) -> 0.48490455 | O10: 40005.19 | P10: =IFERROR((O10/$B$18),0) -> 0.060879799 | Q10: 81951.65 | R10: =IFERROR((Q10/$D$18),0) -> 0.46867884 | T10: =IFERROR((S10/$H$18),0) -> 0 | V10: =IFERROR((U10/$H$18),0) -> 0 | X10: =IFERROR((W10/$H$18),0) -> 0 | Y10: =O10+Q10+U10+W10+S10 -> 121956.84 | Z10: =IFERROR((Y10/$L$18),0) -> 0.14540856 | AC10: =IFERROR((AB10/$B$18),0) -> 0 | AE10: =IFERROR((AD10/$D$18),0) -> 0 | AG10: =IFERROR((AF10/$H$18),0) -> 0 | AI10: =IFERROR((AH10/$H$18),0) -> 0 | AK10: =IFERROR((AJ10/$H$18),0) -> 0 | AL10: =AB10+AD10+AH10+AJ10+AF10 -> 0 | AM10: =IFERROR((AL10/$L$18),0) -> 0 | AP10: =IFERROR((AO10/$B$18),0) -> 0 | AR10: =IFERROR((AQ10/$D$18),0) -> 0 | AT10: =IFERROR((AS10/$H$18),0) -> 0 | AV10: =IFERROR((AU10/$H$18),0) -> 0 | AX10: =IFERROR((AW10/$H$18),0) -> 0 | AY10: =AO10+AQ10+AU10+AW10+AS10 -> 0 | AZ10: =IFERROR((AY10/$L$18),0) -> 0
A11: بنك كريدي - تحصيل | B11: 81005.25 | C11: =IFERROR((B11/$B$18),0) -> 0.12327359 | D11: 18945.227 | E11: =IFERROR((D11/$D$18),0) -> 0.10834714 | G11: =IFERROR((F11/$H$18),0) -> 0 | I11: =IFERROR((H11/$H$18),0) -> 0 | K11: =IFERROR((J11/$H$18),0) -> 0 | L11: =B11+D11+H11+J11+F11 -> 99950.477 | M11: =IFERROR((L11/$L$18),0) -> 0.11917048 | O11: 20066.756 | P11: =IFERROR((O11/$B$18),0) -> 0.030537539 | Q11: 41885.994 | R11: =IFERROR((Q11/$D$18),0) -> 0.23954465 | T11: =IFERROR((S11/$H$18),0) -> 0 | V11: =IFERROR((U11/$H$18),0) -> 0 | X11: =IFERROR((W11/$H$18),0) -> 0 | Y11: =O11+Q11+U11+W11+S11 -> 61952.75 | Z11: =IFERROR((Y11/$L$18),0) -> 0.073865971 | AC11: =IFERROR((AB11/$B$18),0) -> 0 | AE11: =IFERROR((AD11/$D$18),0) -> 0 | AG11: =IFERROR((AF11/$H$18),0) -> 0 | AI11: =IFERROR((AH11/$H$18),0) -> 0 | AK11: =IFERROR((AJ11/$H$18),0) -> 0 | AL11: =AB11+AD11+AH11+AJ11+AF11 -> 0 | AM11: =IFERROR((AL11/$L$18),0) -> 0 | AP11: =IFERROR((AO11/$B$18),0) -> 0 | AR11: =IFERROR((AQ11/$D$18),0) -> 0 | AT11: =IFERROR((AS11/$H$18),0) -> 0 | AV11: =IFERROR((AU11/$H$18),0) -> 0 | AX11: =IFERROR((AW11/$H$18),0) -> 0 | AY11: =AO11+AQ11+AU11+AW11+AS11 -> 0 | AZ11: =IFERROR((AY11/$L$18),0) -> 0
A12: شركه ماني - تحصيل | B12: 42995.73 | C12: =IFERROR((B12/$B$18),0) -> 0.065430795 | D12: 11737.56 | E12: =IFERROR((D12/$D$18),0) -> 0.067126727 | G12: =IFERROR((F12/$H$18),0) -> 0 | I12: =IFERROR((H12/$H$18),0) -> 0 | K12: =IFERROR((J12/$H$18),0) -> 0 | L12: =B12+D12+H12+J12+F12 -> 54733.29 | M12: =IFERROR((L12/$L$18),0) -> 0.065258243 | O12: 30877.18 | P12: =IFERROR((O12/$B$18),0) -> 0.046988816 | Q12: 7741.34 | R12: =IFERROR((Q12/$D$18),0) -> 0.044272474 | T12: =IFERROR((S12/$H$18),0) -> 0 | V12: =IFERROR((U12/$H$18),0) -> 0 | X12: =IFERROR((W12/$H$18),0) -> 0 | Y12: =O12+Q12+U12+W12+S12 -> 38618.52 | Z12: =IFERROR((Y12/$L$18),0) -> 0.046044679 | AC12: =IFERROR((AB12/$B$18),0) -> 0 | AE12: =IFERROR((AD12/$D$18),0) -> 0 | AG12: =IFERROR((AF12/$H$18),0) -> 0 | AI12: =IFERROR((AH12/$H$18),0) -> 0 | AK12: =IFERROR((AJ12/$H$18),0) -> 0 | AL12: =AB12+AD12+AH12+AJ12+AF12 -> 0 | AM12: =IFERROR((AL12/$L$18),0) -> 0 | AP12: =IFERROR((AO12/$B$18),0) -> 0 | AR12: =IFERROR((AQ12/$D$18),0) -> 0 | AT12: =IFERROR((AS12/$H$18),0) -> 0 | AV12: =IFERROR((AU12/$H$18),0) -> 0 | AX12: =IFERROR((AW12/$H$18),0) -> 0 | AY12: =AO12+AQ12+AU12+AW12+AS12 -> 0 | AZ12: =IFERROR((AY12/$L$18),0) -> 0
A13: شركه ميد تقسيط - تحصيل | B13: 30518.176 | C13: =IFERROR((B13/$B$18),0) -> 0.046442484 | D13: 2749.2192 | E13: =IFERROR((D13/$D$18),0) -> 0.015722696 | G13: =IFERROR((F13/$H$18),0) -> 0 | I13: =IFERROR((H13/$H$18),0) -> 0 | K13: =IFERROR((J13/$H$18),0) -> 0 | L13: =B13+D13+H13+J13+F13 -> 33267.395 | M13: =IFERROR((L13/$L$18),0) -> 0.039664557 | O13: 39834.86 | P13: =IFERROR((O13/$B$18),0) -> 0.060620591 | Q13: 2400.12 | R13: =IFERROR((Q13/$D$18),0) -> 0.013726209 | T13: =IFERROR((S13/$H$18),0) -> 0 | V13: =IFERROR((U13/$H$18),0) -> 0 | X13: =IFERROR((W13/$H$18),0) -> 0 | Y13: =O13+Q13+U13+W13+S13 -> 42234.98 | Z13: =IFERROR((Y13/$L$18),0) -> 0.050356567 | AC13: =IFERROR((AB13/$B$18),0) -> 0 | AE13: =IFERROR((AD13/$D$18),0) -> 0 | AG13: =IFERROR((AF13/$H$18),0) -> 0 | AI13: =IFERROR((AH13/$H$18),0) -> 0 | AK13: =IFERROR((AJ13/$H$18),0) -> 0 | AL13: =AB13+AD13+AH13+AJ13+AF13 -> 0 | AM13: =IFERROR((AL13/$L$18),0) -> 0 | AP13: =IFERROR((AO13/$B$18),0) -> 0 | AR13: =IFERROR((AQ13/$D$18),0) -> 0 | AT13: =IFERROR((AS13/$H$18),0) -> 0 | AV13: =IFERROR((AU13/$H$18),0) -> 0 | AX13: =IFERROR((AW13/$H$18),0) -> 0 | AY13: =AO13+AQ13+AU13+AW13+AS13 -> 0 | AZ13: =IFERROR((AY13/$L$18),0) -> 0
A14: شركه رايه - كوربت | C14: =IFERROR((B14/$B$18),0) -> 0 | E14: =IFERROR((D14/$D$18),0) -> 0 | G14: =IFERROR((F14/$H$18),0) -> 0 | I14: =IFERROR((H14/$H$18),0) -> 0 | K14: =IFERROR((J14/$H$18),0) -> 0 | L14: =B14+D14+H14+J14+F14 -> 0 | M14: =IFERROR((L14/$L$18),0) -> 0 | O14: 3250 | P14: =IFERROR((O14/$B$18),0) -> 0.0049458419 | R14: =IFERROR((Q14/$D$18),0) -> 0 | T14: =IFERROR((S14/$H$18),0) -> 0 | V14: =IFERROR((U14/$H$18),0) -> 0 | X14: =IFERROR((W14/$H$18),0) -> 0 | Y14: =O14+Q14+U14+W14+S14 -> 3250 | Z14: =IFERROR((Y14/$L$18),0) -> 0.0038749596 | AC14: =IFERROR((AB14/$B$18),0) -> 0 | AE14: =IFERROR((AD14/$D$18),0) -> 0 | AG14: =IFERROR((AF14/$H$18),0) -> 0 | AI14: =IFERROR((AH14/$H$18),0) -> 0 | AK14: =IFERROR((AJ14/$H$18),0) -> 0 | AL14: =AB14+AD14+AH14+AJ14+AF14 -> 0 | AM14: =IFERROR((AL14/$L$18),0) -> 0 | AP14: =IFERROR((AO14/$B$18),0) -> 0 | AR14: =IFERROR((AQ14/$D$18),0) -> 0 | AT14: =IFERROR((AS14/$H$18),0) -> 0 | AV14: =IFERROR((AU14/$H$18),0) -> 0 | AX14: =IFERROR((AW14/$H$18),0) -> 0 | AY14: =AO14+AQ14+AU14+AW14+AS14 -> 0 | AZ14: =IFERROR((AY14/$L$18),0) -> 0
A15: الخدمات القانونية | C15: =IFERROR((B15/$B$18),0) -> 0 | E15: =IFERROR((D15/$D$18),0) -> 0 | G15: =IFERROR((F15/$H$18),0) -> 0 | I15: =IFERROR((H15/$H$18),0) -> 0 | K15: =IFERROR((J15/$H$18),0) -> 0 | L15: =B15+D15+H15+J15+F15 -> 0 | M15: =IFERROR((L15/$L$18),0) -> 0 | P15: =IFERROR((O15/$B$18),0) -> 0 | R15: =IFERROR((Q15/$D$18),0) -> 0 | T15: =IFERROR((S15/$H$18),0) -> 0 | U15: 3000 | V15: =IFERROR((U15/$H$18),0) -> 0 | X15: =IFERROR((W15/$H$18),0) -> 0 | Y15: =O15+Q15+U15+W15+S15 -> 3000 | Z15: =IFERROR((Y15/$L$18),0) -> 0.0035768858 | AC15: =IFERROR((AB15/$B$18),0) -> 0 | AE15: =IFERROR((AD15/$D$18),0) -> 0 | AG15: =IFERROR((AF15/$H$18),0) -> 0 | AI15: =IFERROR((AH15/$H$18),0) -> 0 | AK15: =IFERROR((AJ15/$H$18),0) -> 0 | AL15: =AB15+AD15+AH15+AJ15+AF15 -> 0 | AM15: =IFERROR((AL15/$L$18),0) -> 0 | AP15: =IFERROR((AO15/$B$18),0) -> 0 | AR15: =IFERROR((AQ15/$D$18),0) -> 0 | AT15: =IFERROR((AS15/$H$18),0) -> 0 | AV15: =IFERROR((AU15/$H$18),0) -> 0 | AX15: =IFERROR((AW15/$H$18),0) -> 0 | AY15: =AO15+AQ15+AU15+AW15+AS15 -> 0 | AZ15: =IFERROR((AY15/$L$18),0) -> 0
C16: =IFERROR((B16/$B$18),0) -> 0 | E16: =IFERROR((D16/$D$18),0) -> 0 | G16: =IFERROR((F16/$H$18),0) -> 0 | I16: =IFERROR((H16/$H$18),0) -> 0 | K16: =IFERROR((J16/$H$18),0) -> 0 | L16: =B16+D16+H16+J16+F16 -> 0 | M16: =IFERROR((L16/$L$18),0) -> 0 | P16: =IFERROR((O16/$B$18),0) -> 0 | R16: =IFERROR((Q16/$D$18),0) -> 0 | T16: =IFERROR((S16/$H$18),0) -> 0 | V16: =IFERROR((U16/$H$18),0) -> 0 | X16: =IFERROR((W16/$H$18),0) -> 0 | Y16: =O16+Q16+U16+W16+S16 -> 0 | Z16: =IFERROR((Y16/$L$18),0) -> 0 | AC16: =IFERROR((AB16/$B$18),0) -> 0 | AE16: =IFERROR((AD16/$D$18),0) -> 0 | AG16: =IFERROR((AF16/$H$18),0) -> 0 | AI16: =IFERROR((AH16/$H$18),0) -> 0 | AK16: =IFERROR((AJ16/$H$18),0) -> 0 | AL16: =AB16+AD16+AH16+AJ16+AF16 -> 0 | AM16: =IFERROR((AL16/$L$18),0) -> 0 | AP16: =IFERROR((AO16/$B$18),0) -> 0 | AR16: =IFERROR((AQ16/$D$18),0) -> 0 | AT16: =IFERROR((AS16/$H$18),0) -> 0 | AV16: =IFERROR((AU16/$H$18),0) -> 0 | AX16: =IFERROR((AW16/$H$18),0) -> 0 | AY16: =AO16+AQ16+AU16+AW16+AS16 -> 0 | AZ16: =IFERROR((AY16/$L$18),0) -> 0
C17: =IFERROR((B17/$B$18),0) -> 0 | E17: =IFERROR((D17/$D$18),0) -> 0 | G17: =IFERROR((F17/$H$18),0) -> 0 | I17: =IFERROR((H17/$H$18),0) -> 0 | K17: =IFERROR((J17/$H$18),0) -> 0 | L17: =B17+D17+H17+J17+F17 -> 0 | M17: =IFERROR((L17/$L$18),0) -> 0 | P17: =IFERROR((O17/$B$18),0) -> 0 | R17: =IFERROR((Q17/$D$18),0) -> 0 | T17: =IFERROR((S17/$H$18),0) -> 0 | V17: =IFERROR((U17/$H$18),0) -> 0 | X17: =IFERROR((W17/$H$18),0) -> 0 | Y17: =O17+Q17+U17+W17+S17 -> 0 | Z17: =IFERROR((Y17/$L$18),0) -> 0 | AC17: =IFERROR((AB17/$B$18),0) -> 0 | AE17: =IFERROR((AD17/$D$18),0) -> 0 | AG17: =IFERROR((AF17/$H$18),0) -> 0 | AI17: =IFERROR((AH17/$H$18),0) -> 0 | AK17: =IFERROR((AJ17/$H$18),0) -> 0 | AL17: =AB17+AD17+AH17+AJ17+AF17 -> 0 | AM17: =IFERROR((AL17/$L$18),0) -> 0 | AP17: =IFERROR((AO17/$B$18),0) -> 0 | AR17: =IFERROR((AQ17/$D$18),0) -> 0 | AT17: =IFERROR((AS17/$H$18),0) -> 0 | AV17: =IFERROR((AU17/$H$18),0) -> 0 | AX17: =IFERROR((AW17/$H$18),0) -> 0 | AY17: =AO17+AQ17+AU17+AW17+AS17 -> 0 | AZ17: =IFERROR((AY17/$L$18),0) -> 0
A18: الإجمالي | B18: =SUM(B3:B17) -> 657117.64 | C18: =IFERROR((B18/$B$18),0) -> 1 | D18: =SUM(D3:D17) -> 174856.73 | E18: =IFERROR((D18/$D$18),0) -> 1 | F18: =SUM(F3:F17) -> 6744.0439 | G18: =IFERROR((F18/$H$18),0) -> 0 | H18: =SUM(H3:H17) -> 0 | I18: =IFERROR((H18/$H$18),0) -> 0 | J18: =SUM(J3:J17) -> 0 | K18: =IFERROR((J18/$H$18),0) -> 0 | L18: =B18+D18+H18+J18+F18 -> 838718.42 | M18: =IFERROR((L18/$L$18),0) -> 1 | O18: =SUM(O3:O17) -> 252401.39 | P18: =IFERROR((O18/$B$18),0) -> 0.38410381 | Q18: =SUM(Q3:Q17) -> 152521.69 | R18: =IFERROR((Q18/$D$18),0) -> 0.87226665 | S18: =SUM(S3:S17) -> 0 | T18: =IFERROR((S18/$H$18),0) -> 0 | U18: =SUM(U3:U17) -> 3000 | V18: =IFERROR((U18/$H$18),0) -> 0 | W18: =SUM(W3:W17) -> 0 | X18: =IFERROR((W18/$H$18),0) -> 0 | Y18: =O18+Q18+U18+W18+S18 -> 407923.08 | Z18: =IFERROR((Y18/$L$18),0) -> 0.48636476 | AB18: =SUM(AB3:AB17) -> 0 | AC18: =IFERROR((AB18/$B$18),0) -> 0 | AD18: =SUM(AD3:AD17) -> 0 | AE18: =IFERROR((AD18/$D$18),0) -> 0 | AF18: =SUM(AF3:AF17) -> 0 | AG18: =IFERROR((AF18/$H$18),0) -> 0 | AH18: =SUM(AH3:AH17) -> 0 | AI18: =IFERROR((AH18/$H$18),0) -> 0 | AJ18: =SUM(AJ3:AJ17) -> 0 | AK18: =IFERROR((AJ18/$H$18),0) -> 0 | AL18: =AB18+AD18+AH18+AJ18+AF18 -> 0 | AM18: =IFERROR((AL18/$L$18),0) -> 0 | AO18: =SUM(AO3:AO17) -> 0 | AP18: =IFERROR((AO18/$B$18),0) -> 0 | AQ18: =SUM(AQ3:AQ17) -> 0 | AR18: =IFERROR((AQ18/$D$18),0) -> 0 | AS18: =SUM(AS3:AS17) -> 0 | AT18: =IFERROR((AS18/$H$18),0) -> 0 | AU18: =SUM(AU3:AU17) -> 0 | AV18: =IFERROR((AU18/$H$18),0) -> 0 | AW18: =SUM(AW3:AW17) -> 0 | AX18: =IFERROR((AW18/$H$18),0) -> 0 | AY18: =AO18+AQ18+AU18+AW18+AS18 -> 0 | AZ18: =IFERROR((AY18/$L$18),0) -> 0
A20: نوع المصروف | B20: =B2 -> القاهرة | D20: =D2 -> المنصورة | F20: =F2 -> القانونيه | H20: =H2 -> الخدمات القانونية | J20: =J2 -> قيمه | L20: =L2 -> الإجمالي | O20: =O2 -> القاهرة | Q20: =Q2 -> المنصورة | S20: =S2 -> القانونيه | U20: =U2 -> الخدمات القانونية | W20: =W2 -> قيمه | Y20: =Y2 -> الإجمالي | AB20: =AB2 -> القاهرة | AD20: =AD2 -> المنصورة | AF20: =AF2 -> القانونيه | AH20: =AH2 -> الخدمات القانونية | AJ20: =AJ2 -> قيمه | AL20: =AL2 -> الإجمالي | AO20: =AO2 -> القاهرة | AQ20: =AQ2 -> المنصورة | AS20: =AS2 -> القانونيه | AU20: =AU2 -> الخدمات القانونية | AW20: =AW2 -> قيمه | AY20: =AY2 -> الإجمالي
A21: جاري شركاء | B21: =SUMIFS(Table1[[المنصرف ]],Table1[[نوع المصروف ]],$A:$A,Table1[[الشهر ]],$B$1,Table1[الفرع],'تحليلات 2024'!$B$20) -> 0 | C21: =IFERROR((B21/$B$18),0) -> 0 | D21: =SUMIFS(Table1[[المنصرف ]],Table1[[نوع المصروف ]],$A:$A,Table1[[الشهر ]],$B$1,Table1[الفرع],'تحليلات 2024'!$D$20) -> 0 | E21: =IFERROR((D21/$D$18),0) -> 0 | F21: =SUMIFS(Table1[[المنصرف ]],Table1[[نوع المصروف ]],$A:$A,Table1[[الشهر ]],$B$1,Table1[الفرع],'تحليلات 2024'!$F$20) -> 0 | G21: =IFERROR((F21/$F$18),0) -> 0 | H21: =SUMIFS(Table1[[المنصرف ]],Table1[[نوع المصروف ]],$A:$A,Table1[[الشهر ]],$B$1,Table1[الفرع],'تحليلات 2024'!$H$20) -> 0 | I21: =IFERROR((H21/$H$18),0) -> 0 | J21: =SUMIFS(Table1[[المنصرف ]],Table1[[نوع المصروف ]],$A:$A,Table1[[الشهر ]],$B$1,Table1[الفرع],'تحليلات 2024'!$J$20) -> 0 | K21: =IFERROR((J21/$L$18),0) -> 0 | L21: =B21+D21+H21+J21+F21 -> 0 | M21: =IFERROR((L21/$L$18),0) -> 0 | O21: =SUMIFS(Table1[[المنصرف ]],Table1[[نوع المصروف ]],$A:$A,Table1[[الشهر ]],$O$1,Table1[الفرع],'تحليلات 2024'!$B$20) -> 0 | P21: =IFERROR((O21/$B$18),0) -> 0 | Q21: =SUMIFS(Table1[[المنصرف ]],Table1[[نوع المصروف ]],$A:$A,Table1[[الشهر ]],$O$1,Table1[الفرع],'تحليلات 2024'!$D$20) -> 0 | R21: =IFERROR((Q21/$D$18),0) -> 0 | S21: =SUMIFS(Table1[[المنصرف ]],Table1[[نوع المصروف ]],$A:$A,Table1[[الشهر ]],$O$1,Table1[الفرع],'تحليلات 2024'!$F$20) -> 0 | T21: =IFERROR((S21/$F$18),0) -> 0 | U21: =SUMIFS(Table1[[المنصرف ]],Table1[[نوع المصروف ]],$A:$A,Table1[[الشهر ]],$O$1,Table1[الفرع],'تحليلات 2024'!$H$20) -> 0 | V21: =IFERROR((U21/$H$18),0) -> 0 | W21: =SUMIFS(Table1[[المنصرف ]],Table1[[نوع المصروف ]],$A:$A,Table1[[الشهر ]],$O$1,Table1[الفرع],'تحليلات 2024'!$J$20) -> 0 | X21: =IFERROR((W21/$L$18),0) -> 0 | Y21: =O21+Q21+U21+W21+S21 -> 0 | Z21: =IFERROR((Y21/$L$18),0) -> 0 | AB21: =SUMIFS(Table1[[المنصرف ]],Table1[[نوع المصروف ]],$A:$A,Table1[[الشهر ]],$AB$1,Table1[الفرع],'تحليلات 2024'!$B$20) -> 0 | AC21: =IFERROR((AB21/$B$18),0) -> 0 | AD21: =SUMIFS(Table1[[المنصرف ]],Table1[[نوع المصروف ]],$A:$A,Table1[[الشهر ]],$AB$1,Table1[الفرع],'تحليلات 2024'!$D$20) -> 0 | AE21: =IFERROR((AD21/$D$18),0) -> 0 | AF21: =SUMIFS(Table1[[المنصرف ]],Table1[[نوع المصروف ]],$A:$A,Table1[[الشهر ]],$AB$1,Table1[الفرع],'تحليلات 2024'!$F$20) -> 0 | AG21: =IFERROR((AF21/$F$18),0) -> 0 | AH21: =SUMIFS(Table1[[المنصرف ]],Table1[[نوع المصروف ]],$A:$A,Table1[[الشهر ]],$AB$1,Table1[الفرع],'تحليلات 2024'!$H$20) -> 0 | AI21: =IFERROR((AH21/$H$18),0) -> 0 | AJ21: =SUMIFS(Table1[[المنصرف ]],Table1[[نوع المصروف ]],$A:$A,Table1[[الشهر ]],$AB$1,Table1[الفرع],'تحليلات 2024'!$J$20) -> 0 | AK21: =IFERROR((AJ21/$L$18),0) -> 0 | AL21: =AB21+AD21+AH21+AJ21+AF21 -> 0 | AM21: =IFERROR((AL21/$L$18),0) -> 0 | AO21: =SUMIFS(Table1[[المنصرف ]],Table1[[نوع المصروف ]],$A:$A,Table1[[الشهر ]],$AO$1,Table1[الفرع],'تحليلات 2024'!$B$20) -> 0 | AP21: =IFERROR((AO21/$B$18),0) -> 0 | AQ21: =SUMIFS(Table1[[المنصرف ]],Table1[[نوع المصروف ]],$A:$A,Table1[[الشهر ]],$AO$1,Table1[الفرع],'تحليلات 2024'!$D$20) -> 0 | AR21: =IFERROR((AQ21/$D$18),0) -> 0 | AS21: =SUMIFS(Table1[[المنصرف ]],Table1[[نوع المصروف ]],$A:$A,Table1[[الشهر ]],$AO$1,Table1[الفرع],'تحليلات 2024'!$F$20) -> 0 | AT21: =IFERROR((AS21/$F$18),0) -> 0 | AU21: =SUMIFS(Table1[[المنصرف ]],Table1[[نوع المصروف ]],$A:$A,Table1[[الشهر ]],$AO$1,Table1[الفرع],'تحليلات 2024'!$H$20) -> 0 | AV21: =IFERROR((AU21/$H$18),0) -> 0 | AW21: =SUMIFS(Table1[[المنصرف ]],Table1[[نوع المصروف ]],$A:$A,Table1[[الشهر ]],$AO$1,Table1[الفرع],'تحليلات 2024'!$J$20) -> 0 | AX21: =IFERROR((AW21/$L$18),0) -> 0 | AY21: =AO21+AQ21+AU21+AW21+AS21 -> 0 | AZ21: =IFERROR((AY21/$L$18),0) -> 0
A22: مرتبات -الادارة العليا | B22: =SUMIFS(Table1[[المنصرف ]],Table1[[نوع المصروف ]],$A:$A,Table1[[الشهر ]],$B$1,Table1[الفرع],'تحليلات 2024'!$B$20) -> 0 | C22: =IFERROR((B22/$B$18),0) -> 0 | D22: =SUMIFS(Table1[[المنصرف ]],Table1[[نوع المصروف ]],$A:$A,Table1[[الشهر ]],$B$1,Table1[الفرع],'تحليلات 2024'!$D$20) -> 0 | E22: =IFERROR((D22/$D$18),0) -> 0 | F22: =SUMIFS(Table1[[المنصرف ]],Table1[[نوع المصروف ]],$A:$A,Table1[[الشهر ]],$B$1,Table1[الفرع],'تحليلات 2024'!$F$20) -> 0 | G22: =IFERROR((F22/$H$18),0) -> 0 | H22: =SUMIFS(Table1[[المنصرف ]],Table1[[نوع المصروف ]],$A:$A,Table1[[الشهر ]],$B$1,Table1[الفرع],'تحليلات 2024'!$H$20) -> 0 | I22: =IFERROR((H22/$H$18),0) -> 0 | J22: =SUMIFS(Table1[[المنصرف ]],Table1[[نوع المصروف ]],$A:$A,Table1[[الشهر ]],$B$1,Table1[الفرع],'تحليلات 2024'!$J$20) -> 0 | K22: =IFERROR((J22/$L$18),0) -> 0 | L22: =B22+D22+H22+J22+F22 -> 0 | M22: =IFERROR((L22/$L$18),0) -> 0 | O22: =SUMIFS(Table1[[المنصرف ]],Table1[[نوع المصروف ]],$A:$A,Table1[[الشهر ]],$O$1,Table1[الفرع],'تحليلات 2024'!$B$20) -> 0 | P22: =IFERROR((O22/$B$18),0) -> 0 | Q22: =SUMIFS(Table1[[المنصرف ]],Table1[[نوع المصروف ]],$A:$A,Table1[[الشهر ]],$O$1,Table1[الفرع],'تحليلات 2024'!$D$20) -> 0 | R22: =IFERROR((Q22/$D$18),0) -> 0 | S22: =SUMIFS(Table1[[المنصرف ]],Table1[[نوع المصروف ]],$A:$A,Table1[[الشهر ]],$O$1,Table1[الفرع],'تحليلات 2024'!$F$20) -> 0 | T22: =IFERROR((S22/$H$18),0) -> 0 | U22: =SUMIFS(Table1[[المنصرف ]],Table1[[نوع المصروف ]],$A:$A,Table1[[الشهر ]],$O$1,Table1[الفرع],'تحليلات 2024'!$H$20) -> 0 | V22: =IFERROR((U22/$H$18),0) -> 0 | W22: =SUMIFS(Table1[[المنصرف ]],Table1[[نوع المصروف ]],$A:$A,Table1[[الشهر ]],$O$1,Table1[الفرع],'تحليلات 2024'!$J$20) -> 0 | X22: =IFERROR((W22/$L$18),0) -> 0 | Y22: =O22+Q22+U22+W22+S22 -> 0 | Z22: =IFERROR((Y22/$L$18),0) -> 0 | AB22: =SUMIFS(Table1[[المنصرف ]],Table1[[نوع المصروف ]],$A:$A,Table1[[الشهر ]],$AB$1,Table1[الفرع],'تحليلات 2024'!$B$20) -> 0 | AC22: =IFERROR((AB22/$B$18),0) -> 0 | AD22: =SUMIFS(Table1[[المنصرف ]],Table1[[نوع المصروف ]],$A:$A,Table1[[الشهر ]],$AB$1,Table1[الفرع],'تحليلات 2024'!$D$20) -> 0 | AE22: =IFERROR((AD22/$D$18),0) -> 0 | AF22: =SUMIFS(Table1[[المنصرف ]],Table1[[نوع المصروف ]],$A:$A,Table1[[الشهر ]],$AB$1,Table1[الفرع],'تحليلات 2024'!$F$20) -> 0 | AG22: =IFERROR((AF22/$H$18),0) -> 0 | AH22: =SUMIFS(Table1[[المنصرف ]],Table1[[نوع المصروف ]],$A:$A,Table1[[الشهر ]],$AB$1,Table1[الفرع],'تحليلات 2024'!$H$20) -> 0 | AI22: =IFERROR((AH22/$H$18),0) -> 0 | AJ22: =SUMIFS(Table1[[المنصرف ]],Table1[[نوع المصروف ]],$A:$A,Table1[[الشهر ]],$AB$1,Table1[الفرع],'تحليلات 2024'!$J$20) -> 0 | AK22: =IFERROR((AJ22/$L$18),0) -> 0 | AL22: =AB22+AD22+AH22+AJ22+AF22 -> 0 | AM22: =IFERROR((AL22/$L$18),0) -> 0 | AO22: =SUMIFS(Table1[[المنصرف ]],Table1[[نوع المصروف ]],$A:$A,Table1[[الشهر ]],$AO$1,Table1[الفرع],'تحليلات 2024'!$B$20) -> 0 | AP22: =IFERROR((AO22/$B$18),0) -> 0 | AQ22: =SUMIFS(Table1[[المنصرف ]],Table1[[نوع المصروف ]],$A:$A,Table1[[الشهر ]],$AO$1,Table1[الفرع],'تحليلات 2024'!$D$20) -> 0 | AR22: =IFERROR((AQ22/$D$18),0) -> 0 | AS22: =SUMIFS(Table1[[المنصرف ]],Table1[[نوع المصروف ]],$A:$A,Table1[[الشهر ]],$AO$1,Table1[الفرع],'تحليلات 2024'!$F$20) -> 0 | AT22: =IFERROR((AS22/$H$18),0) -> 0 | AU22: =SUMIFS(Table1[[المنصرف ]],Table1[[نوع المصروف ]],$A:$A,Table1[[الشهر ]],$AO$1,Table1[الفرع],'تحليلات 2024'!$H$20) -> 0 | AV22: =IFERROR((AU22/$H$18),0) -> 0 | AW22: =SUMIFS(Table1[[المنصرف ]],Table1[[نوع المصروف ]],$A:$A,Table1[[الشهر ]],$AO$1,Table1[الفرع],'تحليلات 2024'!$J$20) -> 0 | AX22: =IFERROR((AW22/$L$18),0) -> 0 | AY22: =AO22+AQ22+AU22+AW22+AS22 -> 0 | AZ22: =IFERROR((AY22/$L$18),0) -> 0
A23: مرتبات -الادارة المالية | B23: =SUMIFS(Table1[[المنصرف ]],Table1[[نوع المصروف ]],$A:$A,Table1[[الشهر ]],$B$1,Table1[الفرع],'تحليلات 2024'!$B$20) -> 0 | C23: =IFERROR((B23/$B$18),0) -> 0 | D23: =SUMIFS(Table1[[المنصرف ]],Table1[[نوع المصروف ]],$A:$A,Table1[[الشهر ]],$B$1,Table1[الفرع],'تحليلات 2024'!$D$20) -> 4269.21 | E23: =IFERROR((D23/$D$18),0) -> 0.024415474 | F23: =SUMIFS(Table1[[المنصرف ]],Table1[[نوع المصروف ]],$A:$A,Table1[[الشهر ]],$B$1,Table1[الفرع],'تحليلات 2024'!$F$20) -> 0 | G23: =IFERROR((F23/$H$18),0) -> 0 | H23: =SUMIFS(Table1[[المنصرف ]],Table1[[نوع المصروف ]],$A:$A,Table1[[الشهر ]],$B$1,Table1[الفرع],'تحليلات 2024'!$H$20) -> 0 | I23: =IFERROR((H23/$H$18),0) -> 0 | J23: =SUMIFS(Table1[[المنصرف ]],Table1[[نوع المصروف ]],$A:$A,Table1[[الشهر ]],$B$1,Table1[الفرع],'تحليلات 2024'!$J$20) -> 0 | K23: =IFERROR((J23/$L$18),0) -> 0 | L23: =B23+D23+H23+J23+F23 -> 4269.21 | M23: =IFERROR((L23/$L$18),0) -> 0.0050901589 | O23: =SUMIFS(Table1[[المنصرف ]],Table1[[نوع المصروف ]],$A:$A,Table1[[الشهر ]],$O$1,Table1[الفرع],'تحليلات 2024'!$B$20) -> 0 | P23: =IFERROR((O23/$B$18),0) -> 0 | Q23: =SUMIFS(Table1[[المنصرف ]],Table1[[نوع المصروف ]],$A:$A,Table1[[الشهر ]],$O$1,Table1[الفرع],'تحليلات 2024'!$D$20) -> 0 | R23: =IFERROR((Q23/$D$18),0) -> 0 | S23: =SUMIFS(Table1[[المنصرف ]],Table1[[نوع المصروف ]],$A:$A,Table1[[الشهر ]],$O$1,Table1[الفرع],'تحليلات 2024'!$F$20) -> 0 | T23: =IFERROR((S23/$H$18),0) -> 0 | U23: =SUMIFS(Table1[[المنصرف ]],Table1[[نوع المصروف ]],$A:$A,Table1[[الشهر ]],$O$1,Table1[الفرع],'تحليلات 2024'!$H$20) -> 0 | V23: =IFERROR((U23/$H$18),0) -> 0 | W23: =SUMIFS(Table1[[المنصرف ]],Table1[[نوع المصروف ]],$A:$A,Table1[[الشهر ]],$O$1,Table1[الفرع],'تحليلات 2024'!$J$20) -> 0 | X23: =IFERROR((W23/$L$18),0) -> 0 | Y23: =O23+Q23+U23+W23+S23 -> 0 | Z23: =IFERROR((Y23/$L$18),0) -> 0 | AB23: =SUMIFS(Table1[[المنصرف ]],Table1[[نوع المصروف ]],$A:$A,Table1[[الشهر ]],$AB$1,Table1[الفرع],'تحليلات 2024'!$B$20) -> 0 | AC23: =IFERROR((AB23/$B$18),0) -> 0 | AD23: =SUMIFS(Table1[[المنصرف ]],Table1[[نوع المصروف ]],$A:$A,Table1[[الشهر ]],$AB$1,Table1[الفرع],'تحليلات 2024'!$D$20) -> 0 | AE23: =IFERROR((AD23/$D$18),0) -> 0 | AF23: =SUMIFS(Table1[[المنصرف ]],Table1[[نوع المصروف ]],$A:$A,Table1[[الشهر ]],$AB$1,Table1[الفرع],'تحليلات 2024'!$F$20) -> 0 | AG23: =IFERROR((AF23/$H$18),0) -> 0 | AH23: =SUMIFS(Table1[[المنصرف ]],Table1[[نوع المصروف ]],$A:$A,Table1[[الشهر ]],$AB$1,Table1[الفرع],'تحليلات 2024'!$H$20) -> 0 | AI23: =IFERROR((AH23/$H$18),0) -> 0 | AJ23: =SUMIFS(Table1[[المنصرف ]],Table1[[نوع المصروف ]],$A:$A,Table1[[الشهر ]],$AB$1,Table1[الفرع],'تحليلات 2024'!$J$20) -> 0 | AK23: =IFERROR((AJ23/$L$18),0) -> 0 | AL23: =AB23+AD23+AH23+AJ23+AF23 -> 0 | AM23: =IFERROR((AL23/$L$18),0) -> 0 | AO23: =SUMIFS(Table1[[المنصرف ]],Table1[[نوع المصروف ]],$A:$A,Table1[[الشهر ]],$AO$1,Table1[الفرع],'تحليلات 2024'!$B$20) -> 0 | AP23: =IFERROR((AO23/$B$18),0) -> 0 | AQ23: =SUMIFS(Table1[[المنصرف ]],Table1[[نوع المصروف ]],$A:$A,Table1[[الشهر ]],$AO$1,Table1[الفرع],'تحليلات 2024'!$D$20) -> 0 | AR23: =IFERROR((AQ23/$D$18),0) -> 0 | AS23: =SUMIFS(Table1[[المنصرف ]],Table1[[نوع المصروف ]],$A:$A,Table1[[الشهر ]],$AO$1,Table1[الفرع],'تحليلات 2024'!$F$20) -> 0 | AT23: =IFERROR((AS23/$H$18),0) -> 0 | AU23: =SUMIFS(Table1[[المنصرف ]],Table1[[نوع المصروف ]],$A:$A,Table1[[الشهر ]],$AO$1,Table1[الفرع],'تحليلات 2024'!$H$20) -> 0 | AV23: =IFERROR((AU23/$H$18),0) -> 0 | AW23: =SUMIFS(Table1[[المنصرف ]],Table1[[نوع المصروف ]],$A:$A,Table1[[الشهر ]],$AO$1,Table1[الفرع],'تحليلات 2024'!$J$20) -> 0 | AX23: =IFERROR((AW23/$L$18),0) -> 0 | AY23: =AO23+AQ23+AU23+AW23+AS23 -> 0 | AZ23: =IFERROR((AY23/$L$18),0) -> 0
A24: مرتبات -اداره الموارد البشرية | B24: =SUMIFS(Table1[[المنصرف ]],Table1[[نوع المصروف ]],$A:$A,Table1[[الشهر ]],$B$1,Table1[الفرع],'تحليلات 2024'!$B$20) -> 0 | C24: =IFERROR((B24/$B$18),0) -> 0 | D24: =SUMIFS(Table1[[المنصرف ]],Table1[[نوع المصروف ]],$A:$A,Table1[[الشهر ]],$B$1,Table1[الفرع],'تحليلات 2024'!$D$20) -> 0 | E24: =IFERROR((D24/$D$18),0) -> 0 | F24: =SUMIFS(Table1[[المنصرف ]],Table1[[نوع المصروف ]],$A:$A,Table1[[الشهر ]],$B$1,Table1[الفرع],'تحليلات 2024'!$F$20) -> 0 | G24: =IFERROR((F24/$H$18),0) -> 0 | H24: =SUMIFS(Table1[[المنصرف ]],Table1[[نوع المصروف ]],$A:$A,Table1[[الشهر ]],$B$1,Table1[الفرع],'تحليلات 2024'!$H$20) -> 0 | I24: =IFERROR((H24/$H$18),0) -> 0 | J24: =SUMIFS(Table1[[المنصرف ]],Table1[[نوع المصروف ]],$A:$A,Table1[[الشهر ]],$B$1,Table1[الفرع],'تحليلات 2024'!$J$20) -> 0 | K24: =IFERROR((J24/$L$18),0) -> 0 | L24: =B24+D24+H24+J24+F24 -> 0 | M24: =IFERROR((L24/$L$18),0) -> 0 | O24: =SUMIFS(Table1[[المنصرف ]],Table1[[نوع المصروف ]],$A:$A,Table1[[الشهر ]],$O$1,Table1[الفرع],'تحليلات 2024'!$B$20) -> 0 | P24: =IFERROR((O24/$B$18),0) -> 0 | Q24: =SUMIFS(Table1[[المنصرف ]],Table1[[نوع المصروف ]],$A:$A,Table1[[الشهر ]],$O$1,Table1[الفرع],'تحليلات 2024'!$D$20) -> 0 | R24: =IFERROR((Q24/$D$18),0) -> 0 | S24: =SUMIFS(Table1[[المنصرف ]],Table1[[نوع المصروف ]],$A:$A,Table1[[الشهر ]],$O$1,Table1[الفرع],'تحليلات 2024'!$F$20) -> 0 | T24: =IFERROR((S24/$H$18),0) -> 0 | U24: =SUMIFS(Table1[[المنصرف ]],Table1[[نوع المصروف ]],$A:$A,Table1[[الشهر ]],$O$1,Table1[الفرع],'تحليلات 2024'!$H$20) -> 0 | V24: =IFERROR((U24/$H$18),0) -> 0 | W24: =SUMIFS(Table1[[المنصرف ]],Table1[[نوع المصروف ]],$A:$A,Table1[[الشهر ]],$O$1,Table1[الفرع],'تحليلات 2024'!$J$20) -> 0 | X24: =IFERROR((W24/$L$18),0) -> 0 | Y24: =O24+Q24+U24+W24+S24 -> 0 | Z24: =IFERROR((Y24/$L$18),0) -> 0 | AB24: =SUMIFS(Table1[[المنصرف ]],Table1[[نوع المصروف ]],$A:$A,Table1[[الشهر ]],$AB$1,Table1[الفرع],'تحليلات 2024'!$B$20) -> 0 | AC24: =IFERROR((AB24/$B$18),0) -> 0 | AD24: =SUMIFS(Table1[[المنصرف ]],Table1[[نوع المصروف ]],$A:$A,Table1[[الشهر ]],$AB$1,Table1[الفرع],'تحليلات 2024'!$D$20) -> 0 | AE24: =IFERROR((AD24/$D$18),0) -> 0 | AF24: =SUMIFS(Table1[[المنصرف ]],Table1[[نوع المصروف ]],$A:$A,Table1[[الشهر ]],$AB$1,Table1[الفرع],'تحليلات 2024'!$F$20) -> 0 | AG24: =IFERROR((AF24/$H$18),0) -> 0 | AH24: =SUMIFS(Table1[[المنصرف ]],Table1[[نوع المصروف ]],$A:$A,Table1[[الشهر ]],$AB$1,Table1[الفرع],'تحليلات 2024'!$H$20) -> 0 | AI24: =IFERROR((AH24/$H$18),0) -> 0 | AJ24: =SUMIFS(Table1[[المنصرف ]],Table1[[نوع المصروف ]],$A:$A,Table1[[الشهر ]],$AB$1,Table1[الفرع],'تحليلات 2024'!$J$20) -> 0 | AK24: =IFERROR((AJ24/$L$18),0) -> 0 | AL24: =AB24+AD24+AH24+AJ24+AF24 -> 0 | AM24: =IFERROR((AL24/$L$18),0) -> 0 | AO24: =SUMIFS(Table1[[المنصرف ]],Table1[[نوع المصروف ]],$A:$A,Table1[[الشهر ]],$AO$1,Table1[الفرع],'تحليلات 2024'!$B$20) -> 0 | AP24: =IFERROR((AO24/$B$18),0) -> 0 | AQ24: =SUMIFS(Table1[[المنصرف ]],Table1[[نوع المصروف ]],$A:$A,Table1[[الشهر ]],$AO$1,Table1[الفرع],'تحليلات 2024'!$D$20) -> 0 | AR24: =IFERROR((AQ24/$D$18),0) -> 0 | AS24: =SUMIFS(Table1[[المنصرف ]],Table1[[نوع المصروف ]],$A:$A,Table1[[الشهر ]],$AO$1,Table1[الفرع],'تحليلات 2024'!$F$20) -> 0 | AT24: =IFERROR((AS24/$H$18),0) -> 0 | AU24: =SUMIFS(Table1[[المنصرف ]],Table1[[نوع المصروف ]],$A:$A,Table1[[الشهر ]],$AO$1,Table1[الفرع],'تحليلات 2024'!$H$20) -> 0 | AV24: =IFERROR((AU24/$H$18),0) -> 0 | AW24: =SUMIFS(Table1[[المنصرف ]],Table1[[نوع المصروف ]],$A:$A,Table1[[الشهر ]],$AO$1,Table1[الفرع],'تحليلات 2024'!$J$20) -> 0 | AX24: =IFERROR((AW24/$L$18),0) -> 0 | AY24: =AO24+AQ24+AU24+AW24+AS24 -> 0 | AZ24: =IFERROR((AY24/$L$18),0) -> 0
A25: مرتبات -الشئون الإدارية | B25: =SUMIFS(Table1[[المنصرف ]],Table1[[نوع المصروف ]],$A:$A,Table1[[الشهر ]],$B$1,Table1[الفرع],'تحليلات 2024'!$B$20) -> 0 | C25: =IFERROR((B25/$B$18),0) -> 0 | D25: =SUMIFS(Table1[[المنصرف ]],Table1[[نوع المصروف ]],$A:$A,Table1[[الشهر ]],$B$1,Table1[الفرع],'تحليلات 2024'!$D$20) -> 0 | E25: =IFERROR((D25/$D$18),0) -> 0 | F25: =SUMIFS(Table1[[المنصرف ]],Table1[[نوع المصروف ]],$A:$A,Table1[[الشهر ]],$B$1,Table1[الفرع],'تحليلات 2024'!$F$20) -> 0 | G25: =IFERROR((F25/$H$18),0) -> 0 | H25: =SUMIFS(Table1[[المنصرف ]],Table1[[نوع المصروف ]],$A:$A,Table1[[الشهر ]],$B$1,Table1[الفرع],'تحليلات 2024'!$H$20) -> 0 | I25: =IFERROR((H25/$H$18),0) -> 0 | J25: =SUMIFS(Table1[[المنصرف ]],Table1[[نوع المصروف ]],$A:$A,Table1[[الشهر ]],$B$1,Table1[الفرع],'تحليلات 2024'!$J$20) -> 0 | K25: =IFERROR((J25/$L$18),0) -> 0 | L25: =B25+D25+H25+J25+F25 -> 0 | M25: =IFERROR((L25/$L$18),0) -> 0 | O25: =SUMIFS(Table1[[المنصرف ]],Table1[[نوع المصروف ]],$A:$A,Table1[[الشهر ]],$O$1,Table1[الفرع],'تحليلات 2024'!$B$20) -> 0 | P25: =IFERROR((O25/$B$18),0) -> 0 | Q25: =SUMIFS(Table1[[المنصرف ]],Table1[[نوع المصروف ]],$A:$A,Table1[[الشهر ]],$O$1,Table1[الفرع],'تحليلات 2024'!$D$20) -> 0 | R25: =IFERROR((Q25/$D$18),0) -> 0 | S25: =SUMIFS(Table1[[المنصرف ]],Table1[[نوع المصروف ]],$A:$A,Table1[[الشهر ]],$O$1,Table1[الفرع],'تحليلات 2024'!$F$20) -> 0 | T25: =IFERROR((S25/$H$18),0) -> 0 | U25: =SUMIFS(Table1[[المنصرف ]],Table1[[نوع المصروف ]],$A:$A,Table1[[الشهر ]],$O$1,Table1[الفرع],'تحليلات 2024'!$H$20) -> 0 | V25: =IFERROR((U25/$H$18),0) -> 0 | W25: =SUMIFS(Table1[[المنصرف ]],Table1[[نوع المصروف ]],$A:$A,Table1[[الشهر ]],$O$1,Table1[الفرع],'تحليلات 2024'!$J$20) -> 0 | X25: =IFERROR((W25/$L$18),0) -> 0 | Y25: =O25+Q25+U25+W25+S25 -> 0 | Z25: =IFERROR((Y25/$L$18),0) -> 0 | AB25: =SUMIFS(Table1[[المنصرف ]],Table1[[نوع المصروف ]],$A:$A,Table1[[الشهر ]],$AB$1,Table1[الفرع],'تحليلات 2024'!$B$20) -> 0 | AC25: =IFERROR((AB25/$B$18),0) -> 0 | AD25: =SUMIFS(Table1[[المنصرف ]],Table1[[نوع المصروف ]],$A:$A,Table1[[الشهر ]],$AB$1,Table1[الفرع],'تحليلات 2024'!$D$20) -> 0 | AE25: =IFERROR((AD25/$D$18),0) -> 0 | AF25: =SUMIFS(Table1[[المنصرف ]],Table1[[نوع المصروف ]],$A:$A,Table1[[الشهر ]],$AB$1,Table1[الفرع],'تحليلات 2024'!$F$20) -> 0 | AG25: =IFERROR((AF25/$H$18),0) -> 0 | AH25: =SUMIFS(Table1[[المنصرف ]],Table1[[نوع المصروف ]],$A:$A,Table1[[الشهر ]],$AB$1,Table1[الفرع],'تحليلات 2024'!$H$20) -> 0 | AI25: =IFERROR((AH25/$H$18),0) -> 0 | AJ25: =SUMIFS(Table1[[المنصرف ]],Table1[[نوع المصروف ]],$A:$A,Table1[[الشهر ]],$AB$1,Table1[الفرع],'تحليلات 2024'!$J$20) -> 0 | AK25: =IFERROR((AJ25/$L$18),0) -> 0 | AL25: =AB25+AD25+AH25+AJ25+AF25 -> 0 | AM25: =IFERROR((AL25/$L$18),0) -> 0 | AO25: =SUMIFS(Table1[[المنصرف ]],Table1[[نوع المصروف ]],$A:$A,Table1[[الشهر ]],$AO$1,Table1[الفرع],'تحليلات 2024'!$B$20) -> 0 | AP25: =IFERROR((AO25/$B$18),0) -> 0 | AQ25: =SUMIFS(Table1[[المنصرف ]],Table1[[نوع المصروف ]],$A:$A,Table1[[الشهر ]],$AO$1,Table1[الفرع],'تحليلات 2024'!$D$20) -> 0 | AR25: =IFERROR((AQ25/$D$18),0) -> 0 | AS25: =SUMIFS(Table1[[المنصرف ]],Table1[[نوع المصروف ]],$A:$A,Table1[[الشهر ]],$AO$1,Table1[الفرع],'تحليلات 2024'!$F$20) -> 0 | AT25: =IFERROR((AS25/$H$18),0) -> 0 | AU25: =SUMIFS(Table1[[المنصرف ]],Table1[[نوع المصروف ]],$A:$A,Table1[[الشهر ]],$AO$1,Table1[الفرع],'تحليلات 2024'!$H$20) -> 0 | AV25: =IFERROR((AU25/$H$18),0) -> 0 | AW25: =SUMIFS(Table1[[المنصرف ]],Table1[[نوع المصروف ]],$A:$A,Table1[[الشهر ]],$AO$1,Table1[الفرع],'تحليلات 2024'!$J$20) -> 0 | AX25: =IFERROR((AW25/$L$18),0) -> 0 | AY25: =AO25+AQ25+AU25+AW25+AS25 -> 0 | AZ25: =IFERROR((AY25/$L$18),0) -> 0
A26: مرتبات -الخدمات المعاونة | B26: =SUMIFS(Table1[[المنصرف ]],Table1[[نوع المصروف ]],$A:$A,Table1[[الشهر ]],$B$1,Table1[الفرع],'تحليلات 2024'!$B$20) -> 0 | C26: =IFERROR((B26/$B$18),0) -> 0 | D26: =SUMIFS(Table1[[المنصرف ]],Table1[[نوع المصروف ]],$A:$A,Table1[[الشهر ]],$B$1,Table1[الفرع],'تحليلات 2024'!$D$20) -> 0 | E26: =IFERROR((D26/$D$18),0) -> 0 | F26: =SUMIFS(Table1[[المنصرف ]],Table1[[نوع المصروف ]],$A:$A,Table1[[الشهر ]],$B$1,Table1[الفرع],'تحليلات 2024'!$F$20) -> 0 | G26: =IFERROR((F26/$H$18),0) -> 0 | H26: =SUMIFS(Table1[[المنصرف ]],Table1[[نوع المصروف ]],$A:$A,Table1[[الشهر ]],$B$1,Table1[الفرع],'تحليلات 2024'!$H$20) -> 0 | I26: =IFERROR((H26/$H$18),0) -> 0 | J26: =SUMIFS(Table1[[المنصرف ]],Table1[[نوع المصروف ]],$A:$A,Table1[[الشهر ]],$B$1,Table1[الفرع],'تحليلات 2024'!$J$20) -> 0 | K26: =IFERROR((J26/$L$18),0) -> 0 | L26: =B26+D26+H26+J26+F26 -> 0 | M26: =IFERROR((L26/$L$18),0) -> 0 | O26: =SUMIFS(Table1[[المنصرف ]],Table1[[نوع المصروف ]],$A:$A,Table1[[الشهر ]],$O$1,Table1[الفرع],'تحليلات 2024'!$B$20) -> 0 | P26: =IFERROR((O26/$B$18),0) -> 0 | Q26: =SUMIFS(Table1[[المنصرف ]],Table1[[نوع المصروف ]],$A:$A,Table1[[الشهر ]],$O$1,Table1[الفرع],'تحليلات 2024'!$D$20) -> 0 | R26: =IFERROR((Q26/$D$18),0) -> 0 | S26: =SUMIFS(Table1[[المنصرف ]],Table1[[نوع المصروف ]],$A:$A,Table1[[الشهر ]],$O$1,Table1[الفرع],'تحليلات 2024'!$F$20) -> 0 | T26: =IFERROR((S26/$H$18),0) -> 0 | U26: =SUMIFS(Table1[[المنصرف ]],Table1[[نوع المصروف ]],$A:$A,Table1[[الشهر ]],$O$1,Table1[الفرع],'تحليلات 2024'!$H$20) -> 0 | V26: =IFERROR((U26/$H$18),0) -> 0 | W26: =SUMIFS(Table1[[المنصرف ]],Table1[[نوع المصروف ]],$A:$A,Table1[[الشهر ]],$O$1,Table1[الفرع],'تحليلات 2024'!$J$20) -> 0 | X26: =IFERROR((W26/$L$18),0) -> 0 | Y26: =O26+Q26+U26+W26+S26 -> 0 | Z26: =IFERROR((Y26/$L$18),0) -> 0 | AB26: =SUMIFS(Table1[[المنصرف ]],Table1[[نوع المصروف ]],$A:$A,Table1[[الشهر ]],$AB$1,Table1[الفرع],'تحليلات 2024'!$B$20) -> 0 | AC26: =IFERROR((AB26/$B$18),0) -> 0 | AD26: =SUMIFS(Table1[[المنصرف ]],Table1[[نوع المصروف ]],$A:$A,Table1[[الشهر ]],$AB$1,Table1[الفرع],'تحليلات 2024'!$D$20) -> 0 | AE26: =IFERROR((AD26/$D$18),0) -> 0 | AF26: =SUMIFS(Table1[[المنصرف ]],Table1[[نوع المصروف ]],$A:$A,Table1[[الشهر ]],$AB$1,Table1[الفرع],'تحليلات 2024'!$F$20) -> 0 | AG26: =IFERROR((AF26/$H$18),0) -> 0 | AH26: =SUMIFS(Table1[[المنصرف ]],Table1[[نوع المصروف ]],$A:$A,Table1[[الشهر ]],$AB$1,Table1[الفرع],'تحليلات 2024'!$H$20) -> 0 | AI26: =IFERROR((AH26/$H$18),0) -> 0 | AJ26: =SUMIFS(Table1[[المنصرف ]],Table1[[نوع المصروف ]],$A:$A,Table1[[الشهر ]],$AB$1,Table1[الفرع],'تحليلات 2024'!$J$20) -> 0 | AK26: =IFERROR((AJ26/$L$18),0) -> 0 | AL26: =AB26+AD26+AH26+AJ26+AF26 -> 0 | AM26: =IFERROR((AL26/$L$18),0) -> 0 | AO26: =SUMIFS(Table1[[المنصرف ]],Table1[[نوع المصروف ]],$A:$A,Table1[[الشهر ]],$AO$1,Table1[الفرع],'تحليلات 2024'!$B$20) -> 0 | AP26: =IFERROR((AO26/$B$18),0) -> 0 | AQ26: =SUMIFS(Table1[[المنصرف ]],Table1[[نوع المصروف ]],$A:$A,Table1[[الشهر ]],$AO$1,Table1[الفرع],'تحليلات 2024'!$D$20) -> 0 | AR26: =IFERROR((AQ26/$D$18),0) -> 0 | AS26: =SUMIFS(Table1[[المنصرف ]],Table1[[نوع المصروف ]],$A:$A,Table1[[الشهر ]],$AO$1,Table1[الفرع],'تحليلات 2024'!$F$20) -> 0 | AT26: =IFERROR((AS26/$H$18),0) -> 0 | AU26: =SUMIFS(Table1[[المنصرف ]],Table1[[نوع المصروف ]],$A:$A,Table1[[الشهر ]],$AO$1,Table1[الفرع],'تحليلات 2024'!$H$20) -> 0 | AV26: =IFERROR((AU26/$H$18),0) -> 0 | AW26: =SUMIFS(Table1[[المنصرف ]],Table1[[نوع المصروف ]],$A:$A,Table1[[الشهر ]],$AO$1,Table1[الفرع],'تحليلات 2024'!$J$20) -> 0 | AX26: =IFERROR((AW26/$L$18),0) -> 0 | AY26: =AO26+AQ26+AU26+AW26+AS26 -> 0 | AZ26: =IFERROR((AY26/$L$18),0) -> 0
A27: مرتبات -الشئون القانونية | B27: =SUMIFS(Table1[[المنصرف ]],Table1[[نوع المصروف ]],$A:$A,Table1[[الشهر ]],$B$1,Table1[الفرع],'تحليلات 2024'!$B$20) -> 0 | C27: =IFERROR((B27/$B$18),0) -> 0 | D27: =SUMIFS(Table1[[المنصرف ]],Table1[[نوع المصروف ]],$A:$A,Table1[[الشهر ]],$B$1,Table1[الفرع],'تحليلات 2024'!$D$20) -> 0 | E27: =IFERROR((D27/$D$18),0) -> 0 | F27: =SUMIFS(Table1[[المنصرف ]],Table1[[نوع المصروف ]],$A:$A,Table1[[الشهر ]],$B$1,Table1[الفرع],'تحليلات 2024'!$F$20) -> 0 | G27: =IFERROR((F27/$H$18),0) -> 0 | H27: =SUMIFS(Table1[[المنصرف ]],Table1[[نوع المصروف ]],$A:$A,Table1[[الشهر ]],$B$1,Table1[الفرع],'تحليلات 2024'!$H$20) -> 0 | I27: =IFERROR((H27/$H$18),0) -> 0 | J27: =SUMIFS(Table1[[المنصرف ]],Table1[[نوع المصروف ]],$A:$A,Table1[[الشهر ]],$B$1,Table1[الفرع],'تحليلات 2024'!$J$20) -> 0 | K27: =IFERROR((J27/$L$18),0) -> 0 | L27: =B27+D27+H27+J27+F27 -> 0 | M27: =IFERROR((L27/$L$18),0) -> 0 | O27: =SUMIFS(Table1[[المنصرف ]],Table1[[نوع المصروف ]],$A:$A,Table1[[الشهر ]],$O$1,Table1[الفرع],'تحليلات 2024'!$B$20) -> 0 | P27: =IFERROR((O27/$B$18),0) -> 0 | Q27: =SUMIFS(Table1[[المنصرف ]],Table1[[نوع المصروف ]],$A:$A,Table1[[الشهر ]],$O$1,Table1[الفرع],'تحليلات 2024'!$D$20) -> 0 | R27: =IFERROR((Q27/$D$18),0) -> 0 | S27: =SUMIFS(Table1[[المنصرف ]],Table1[[نوع المصروف ]],$A:$A,Table1[[الشهر ]],$O$1,Table1[الفرع],'تحليلات 2024'!$F$20) -> 0 | T27: =IFERROR((S27/$H$18),0) -> 0 | U27: =SUMIFS(Table1[[المنصرف ]],Table1[[نوع المصروف ]],$A:$A,Table1[[الشهر ]],$O$1,Table1[الفرع],'تحليلات 2024'!$H$20) -> 0 | V27: =IFERROR((U27/$H$18),0) -> 0 | W27: =SUMIFS(Table1[[المنصرف ]],Table1[[نوع المصروف ]],$A:$A,Table1[[الشهر ]],$O$1,Table1[الفرع],'تحليلات 2024'!$J$20) -> 0 | X27: =IFERROR((W27/$L$18),0) -> 0 | Y27: =O27+Q27+U27+W27+S27 -> 0 | Z27: =IFERROR((Y27/$L$18),0) -> 0 | AB27: =SUMIFS(Table1[[المنصرف ]],Table1[[نوع المصروف ]],$A:$A,Table1[[الشهر ]],$AB$1,Table1[الفرع],'تحليلات 2024'!$B$20) -> 0 | AC27: =IFERROR((AB27/$B$18),0) -> 0 | AD27: =SUMIFS(Table1[[المنصرف ]],Table1[[نوع المصروف ]],$A:$A,Table1[[الشهر ]],$AB$1,Table1[الفرع],'تحليلات 2024'!$D$20) -> 0 | AE27: =IFERROR((AD27/$D$18),0) -> 0 | AF27: =SUMIFS(Table1[[المنصرف ]],Table1[[نوع المصروف ]],$A:$A,Table1[[الشهر ]],$AB$1,Table1[الفرع],'تحليلات 2024'!$F$20) -> 0 | AG27: =IFERROR((AF27/$H$18),0) -> 0 | AH27: =SUMIFS(Table1[[المنصرف ]],Table1[[نوع المصروف ]],$A:$A,Table1[[الشهر ]],$AB$1,Table1[الفرع],'تحليلات 2024'!$H$20) -> 0 | AI27: =IFERROR((AH27/$H$18),0) -> 0 | AJ27: =SUMIFS(Table1[[المنصرف ]],Table1[[نوع المصروف ]],$A:$A,Table1[[الشهر ]],$AB$1,Table1[الفرع],'تحليلات 2024'!$J$20) -> 0 | AK27: =IFERROR((AJ27/$L$18),0) -> 0 | AL27: =AB27+AD27+AH27+AJ27+AF27 -> 0 | AM27: =IFERROR((AL27/$L$18),0) -> 0 | AO27: =SUMIFS(Table1[[المنصرف ]],Table1[[نوع المصروف ]],$A:$A,Table1[[الشهر ]],$AO$1,Table1[الفرع],'تحليلات 2024'!$B$20) -> 0 | AP27: =IFERROR((AO27/$B$18),0) -> 0 | AQ27: =SUMIFS(Table1[[المنصرف ]],Table1[[نوع المصروف ]],$A:$A,Table1[[الشهر ]],$AO$1,Table1[الفرع],'تحليلات 2024'!$D$20) -> 0 | AR27: =IFERROR((AQ27/$D$18),0) -> 0 | AS27: =SUMIFS(Table1[[المنصرف ]],Table1[[نوع المصروف ]],$A:$A,Table1[[الشهر ]],$AO$1,Table1[الفرع],'تحليلات 2024'!$F$20) -> 0 | AT27: =IFERROR((AS27/$H$18),0) -> 0 | AU27: =SUMIFS(Table1[[المنصرف ]],Table1[[نوع المصروف ]],$A:$A,Table1[[الشهر ]],$AO$1,Table1[الفرع],'تحليلات 2024'!$H$20) -> 0 | AV27: =IFERROR((AU27/$H$18),0) -> 0 | AW27: =SUMIFS(Table1[[المنصرف ]],Table1[[نوع المصروف ]],$A:$A,Table1[[الشهر ]],$AO$1,Table1[الفرع],'تحليلات 2024'!$J$20) -> 0 | AX27: =IFERROR((AW27/$L$18),0) -> 0 | AY27: =AO27+AQ27+AU27+AW27+AS27 -> 0 | AZ27: =IFERROR((AY27/$L$18),0) -> 0
